Workbook

Sheet Inputs
A1: BUYER COST MODEL — INPUTS (edit blue cells on yellow; everything else is a formula)
A2: Prepared 2026-10-01 for Taylor Dasch, EG Realty. Illustrative model, NOT a Loan Estimate, not a lender-approved cash-to-close figure.
A4: Global assumption | B4: Value | C4: Unit | D4: Status / source
A5: Interest rate (30-yr fixed) | B5: 0.0671 | C5: % (fraction) | D5: ILLUSTRATIVE. Freddie Mac PMMS 30-yr FRM average, week of Sept 3, 2026 (latest located Oct 1, 2026). Not a quote. Lender must quote per borrower, property type (2-unit), occupancy and points.
A6: Loan term (years) | B6: 30 | C6: years | D6: Assumption
A7: Scenario A down payment (owner-occupied conventional 2-unit) | B7: 0.05 | C7: % of price | D7: Fannie Mae allows 5% down on owner-occupied 2–4 unit (policy effective Nov 2023). Lender must confirm eligibility, MI and reserves.
A8: Scenario B down payment (investment conventional 2-unit) | B8: 0.25 | C8: % of price | D8: Typical conventional minimum for non-owner-occupied 2–4 unit; lender to confirm.
A9: Mortgage insurance, Scenario A (annual % of loan) | B9: 0.0055 | C9: % (fraction) | D9: ILLUSTRATIVE placeholder for 95% LTV conventional MI; lender must quote. Set to 0 if LTV ≤ 80%.
A10: Homeowners insurance (annual, per property) | B10: 2400 | C10: $ / yr | D10: PLACEHOLDER — no quote obtained. Insurer must quote each address (duplex, age of roof, claims history).
A11: Flood insurance (annual) — only where lender requires | B11: 0 | C11: $ / yr | D11: PLACEHOLDER 0. 2201 Westcliff lot is within 30 m of FEMA Zone AE/floodway (see Facts sheet); if the structure is in the SFHA a lender will require NFIP/private flood coverage. Quote required.
A12: Lender + title + other closing costs (% of price) | B12: 0.025 | C12: % of price | D12: ILLUSTRATIVE placeholder for lender fees, title policy, endorsements, recording, survey if needed. Replace with lender worksheet.
A13: Prepaid interest days | B13: 15 | C13: days | D13: Assumption (closing mid-month).
A14: Tax escrow months collected at closing | B14: 3 | C14: months | D14: Assumption; lender sets.
A15: Insurance months collected at closing (12 prepaid + cushion) | B15: 14 | C15: months | D15: Assumption; lender sets.
A16: Maintenance / capital allowance (annual % of price) | B16: 0.01 | C16: % of price | D16: ILLUSTRATIVE allowance shown separately from the payment; not a lender item.
... A18: Earnest money + option fee already paid (credited at closing) | B18: 0 | C18: $ | D18: Enter actual amounts once a contract exists; avoids double counting.
A20: PROPERTY-SPECIFIC INPUTS (from MLS 360 Property View sheets printed 2026-10-01 unless noted)
A21: Field | B21: 3604 Littleleaf Dr, Killeen 76549 (MLS 624332) | C21: 2201 Westcliff Rd, Killeen 76543 (MLS 625203) | D21: 2409 Patrick Henry St, Temple 76504 (MLS 621224) | E21: Source / status
A22: List price ($) | B22: 245000 | C22: 260000 | D22: 219000 | E22: MLS list price, printed 2026-10-01.
A23: Proposed offer price ($) — default = list | B23: 245000 | C23: 260000 | D23: 219000 | E23: INPUT. No offer has been made; defaults to list. Internal comp review required before choosing.
A24: Tax rate (% of taxable value) | B24: 0.0203 | C24: 0.0203 | D24: 0.0239 | E24: MLS 'Tax Rate' field: 2.03 (tax year 2026) for both Killeen sheets; 2.39 (tax year 2025) for Temple. Verify with Bell CAD / tax office; Bell CAD site was unreachable on 2026-10-01.
A25: MLS 'Tax Annl Amt' as listed ($) | B25: 4761 | C25: 5207 | D25: 0 | E25: Littleleaf $4,761 reflects the CURRENT OWNER'S Homestead exemption (MLS Exemptions: Homestead). Westcliff $5,207 lists no exemption. Patrick Henry field BLANK (entered 0 = unknown, not zero tax).
A26: Buyer-treatment taxable value basis ($) — default = offer price | B26: 245000 | C26: 260000 | D26: 219000 | E26: ASSUMPTION: taxable value reset toward purchase price with no exemption. Bell CAD 2026 appraised values not retrieved. Owner-occupant may qualify for homestead on the occupied unit only (Tex. Tax Code §11.13); CAD to confirm.
A27: HOA (annual $) | B27: 0 | C27: 0 | D27: 0 | E27: MLS: HOA None on all three.
A28: Flood insurance required? (1=yes, 0=no, blank=unknown) | B28: 0 | D28: 0 | E28: FEMA NFHL check 2026-10-01: Littleleaf and Patrick Henry sites in Zone X minimal hazard; Westcliff lot within 30 m of Zone AE and floodway — structure location vs SFHA UNKNOWN; MLS 'FEMA Flood Plain: Partial'.
A29: Unit 1 actual monthly rent ($) | B29: 0 | C29: 895 | D29: 995 | E29: Littleleaf: both vacant, no rent data. Westcliff: one side month-to-month $895 (MLS). Patrick Henry: one side leased to 02/28/2027 at $995 (MLS). Actual collections not verified.
A30: Unit 2 actual monthly rent ($) | B30: 0 | C30: 0 | D30: 0 | E30: Vacant units: 0 actual. Patrick Henry MLS shows $995 PRO FORMA for the vacant side (not income).
A31: Pro forma / asking rent, vacant unit ($) — informational only | D31: 995 | E31: Listing agent's pro forma; not used in payment math.
A33: Legend: blue text on yellow = input you may edit. Black = formula or fixed text. Nothing on other sheets is hard-coded.

Sheet Scenarios
A1: MONTHLY PAYMENT AND CASH-TO-CLOSE SCENARIOS (all formulas reference Inputs). ILLUSTRATIVE — not a Loan Estimate.
A3: SCENARIO A — Owner-occupied conventional, 5% down, with MI (no seller credit) | B3: 3604 Littleleaf (Killeen) | C3: 2201 Westcliff (Killeen) | D3: 2409 Patrick Henry (Temple)
A4: Buyer lives in one unit. Littleleaf also allows FHA/VA per MLS; Westcliff and Patrick Henry list Cash/Conventional only.
A5: Offer price ($) | B5: =Inputs!B23 | C5: =Inputs!C23 | D5: =Inputs!D23
A6: Down payment (%) | B6: =Inputs!$B$7 | C6: =Inputs!$B$7 | D6: =Inputs!$B$7
A7: Down payment ($) | B7: =B5*B6 | C7: =C5*C6 | D7: =D5*D6
A8: Loan amount ($) | B8: =B5-B7 | C8: =C5-C7 | D8: =D5-D7
A9: Principal & interest ($/mo) | B9: =B8*(Inputs!$B$5/12)/(1-(1+Inputs!$B$5/12)^(-Inputs!$B$6*12)) | C9: =C8*(Inputs!$B$5/12)/(1-(1+Inputs!$B$5/12)^(-Inputs!$B$6*12)) | D9: =D8*(Inputs!$B$5/12)/(1-(1+Inputs!$B$5/12)^(-Inputs!$B$6*12))
A10: Property tax, buyer treatment ($/mo) = basis × rate / 12 | B10: =Inputs!B26*Inputs!B24/12 | C10: =Inputs!C26*Inputs!C24/12 | D10: =Inputs!D26*Inputs!D24/12
A11: Property tax per MLS annual amount ($/mo) — comparison only | B11: =IF(Inputs!B25=0,"unknown",Inputs!B25/12) | C11: =IF(Inputs!C25=0,"unknown",Inputs!C25/12) | D11: =IF(Inputs!D25=0,"unknown",Inputs!D25/12)
A12: Homeowners insurance ($/mo) — placeholder | B12: =Inputs!$B$10/12 | C12: =Inputs!$B$10/12 | D12: =Inputs!$B$10/12
A13: Flood insurance ($/mo) — if required | B13: =IF(Inputs!B28=1,Inputs!$B$11/12,0) | C13: =IF(Inputs!C28=1,Inputs!$B$11/12,0) | D13: =IF(Inputs!D28=1,Inputs!$B$11/12,0)
A14: Mortgage insurance ($/mo) | B14: =B8*Inputs!$B$9/12 | C14: =C8*Inputs!$B$9/12 | D14: =D8*Inputs!$B$9/12
A15: HOA ($/mo) | B15: =Inputs!B27/12 | C15: =Inputs!C27/12 | D15: =Inputs!D27/12
A16: TOTAL MONTHLY PAYMENT (PITI + MI + HOA) | B16: =B9+B10+B12+B13+B14+B15 | C16: =C9+C10+C12+C13+C14+C15 | D16: =D9+D10+D12+D13+D14+D15
A17: Maintenance allowance ($/mo) — separate, illustrative | B17: =B5*Inputs!$B$16/12 | C17: =C5*Inputs!$B$16/12 | D17: =D5*Inputs!$B$16/12
A18: Actual rent in place ($/mo) — signed lease/MTM only | B18: =Inputs!B29+Inputs!B30 | C18: =Inputs!C29+Inputs!C30 | D18: =Inputs!D29+Inputs!D30
A19: Payment less actual rent in place ($/mo) | B19: =B16-B18 | C19: =C16-C18 | D19: =D16-D18
A20: — CASH TO CLOSE —
A21: Down payment ($) | B21: =B7 | C21: =C7 | D21: =D7
A22: Lender/title/other closing costs ($) — placeholder % | B22: =B5*Inputs!$B$12 | C22: =C5*Inputs!$B$12 | D22: =D5*Inputs!$B$12
A23: Prepaid interest ($) | B23: =B8*Inputs!$B$5/365*Inputs!$B$13 | C23: =C8*Inputs!$B$5/365*Inputs!$B$13 | D23: =D8*Inputs!$B$5/365*Inputs!$B$13
A24: Tax escrow deposit ($) | B24: =B10*Inputs!$B$14 | C24: =C10*Inputs!$B$14 | D24: =D10*Inputs!$B$14
A25: Insurance prepaid + escrow ($) | B25: =(B12+B13)*Inputs!$B$15 | C25: =(C12+C13)*Inputs!$B$15 | D25: =(D12+D13)*Inputs!$B$15
A26: Subtotal before credits ($) | B26: =SUM(B21:B25) | C26: =SUM(C21:C25) | D26: =SUM(D21:D25)
A27: Seller contribution ($) — PROPOSED, capped at non-down-payment costs | B27: =0 | C27: =0 | D27: =0
A28: Earnest/option money already paid ($) | B28: =Inputs!$B$18 | C28: =Inputs!$B$18 | D28: =Inputs!$B$18
A29: ESTIMATED ADDITIONAL CASH DUE AT CLOSING ($) | B29: =B26-B27-B28 | C29: =C26-C27-C28 | D29: =D26-D27-D28
A32: SCENARIO A2 — Same as A, with PROPOSED seller contribution (not accepted) | B32: 3604 Littleleaf (Killeen) | C32: 2201 Westcliff (Killeen) | D32: 2409 Patrick Henry (Temple)
A33: Identical assumptions to A; only the proposed seller credit differs. Program cap must be verified by lender.
A34: Offer price ($) | B34: =Inputs!B23 | C34: =Inputs!C23 | D34: =Inputs!D23
A35: Down payment (%) | B35: =Inputs!$B$7 | C35: =Inputs!$B$7 | D35: =Inputs!$B$7
A36: Down payment ($) | B36: =B34*B35 | C36: =C34*C35 | D36: =D34*D35
A37: Loan amount ($) | B37: =B34-B36 | C37: =C34-C36 | D37: =D34-D36
A38: Principal & interest ($/mo) | B38: =B37*(Inputs!$B$5/12)/(1-(1+Inputs!$B$5/12)^(-Inputs!$B$6*12)) | C38: =C37*(Inputs!$B$5/12)/(1-(1+Inputs!$B$5/12)^(-Inputs!$B$6*12)) | D38: =D37*(Inputs!$B$5/12)/(1-(1+Inputs!$B$5/12)^(-Inputs!$B$6*12))
A39: Property tax, buyer treatment ($/mo) = basis × rate / 12 | B39: =Inputs!B26*Inputs!B24/12 | C39: =Inputs!C26*Inputs!C24/12 | D39: =Inputs!D26*Inputs!D24/12
A40: Property tax per MLS annual amount ($/mo) — comparison only | B40: =IF(Inputs!B25=0,"unknown",Inputs!B25/12) | C40: =IF(Inputs!C25=0,"unknown",Inputs!C25/12) | D40: =IF(Inputs!D25=0,"unknown",Inputs!D25/12)
A41: Homeowners insurance ($/mo) — placeholder | B41: =Inputs!$B$10/12 | C41: =Inputs!$B$10/12 | D41: =Inputs!$B$10/12
A42: Flood insurance ($/mo) — if required | B42: =IF(Inputs!B28=1,Inputs!$B$11/12,0) | C42: =IF(Inputs!C28=1,Inputs!$B$11/12,0) | D42: =IF(Inputs!D28=1,Inputs!$B$11/12,0)
A43: Mortgage insurance ($/mo) | B43: =B37*Inputs!$B$9/12 | C43: =C37*Inputs!$B$9/12 | D43: =D37*Inputs!$B$9/12
...

Sheet Sensitivity
A1: SENSITIVITY — Scenario A total monthly payment under alternative rate, tax and insurance inputs (formulas)
A3: Case | B3: 3604 Littleleaf | C3: 2201 Westcliff | D3: 2409 Patrick Henry
A4: Base (Inputs as entered) | B4: =Scenarios!B8*((Inputs!$B$5+(0))/12)/(1-(1+(Inputs!$B$5+(0))/12)^(-Inputs!$B$6*12))+Inputs!B26*Inputs!B24*1/12+Inputs!$B$10*1/12+IF(Inputs!B28=1,Inputs!$B$11/12,0)+Scenarios!B8*Inputs!$B$9/12+Inputs!B27/12 | C4: =Scenarios!C8*((Inputs!$B$5+(0))/12)/(1-(1+(Inputs!$B$5+(0))/12)^(-Inputs!$B$6*12))+Inputs!C26*Inputs!C24*1/12+Inputs!$B$10*1/12+IF(Inputs!C28=1,Inputs!$B$11/12,0)+Scenarios!C8*Inputs!$B$9/12+Inputs!C27/12 | D4: =Scenarios!D8*((Inputs!$B$5+(0))/12)/(1-(1+(Inputs!$B$5+(0))/12)^(-Inputs!$B$6*12))+Inputs!D26*Inputs!D24*1/12+Inputs!$B$10*1/12+IF(Inputs!D28=1,Inputs!$B$11/12,0)+Scenarios!D8*Inputs!$B$9/12+Inputs!D27/12
A5: Rate +0.50 pt | B5: =Scenarios!B8*((Inputs!$B$5+(0.005))/12)/(1-(1+(Inputs!$B$5+(0.005))/12)^(-Inputs!$B$6*12))+Inputs!B26*Inputs!B24*1/12+Inputs!$B$10*1/12+IF(Inputs!B28=1,Inputs!$B$11/12,0)+Scenarios!B8*Inputs!$B$9/12+Inputs!B27/12 | C5: =Scenarios!C8*((Inputs!$B$5+(0.005))/12)/(1-(1+(Inputs!$B$5+(0.005))/12)^(-Inputs!$B$6*12))+Inputs!C26*Inputs!C24*1/12+Inputs!$B$10*1/12+IF(Inputs!C28=1,Inputs!$B$11/12,0)+Scenarios!C8*Inputs!$B$9/12+Inputs!C27/12 | D5: =Scenarios!D8*((Inputs!$B$5+(0.005))/12)/(1-(1+(Inputs!$B$5+(0.005))/12)^(-Inputs!$B$6*12))+Inputs!D26*Inputs!D24*1/12+Inputs!$B$10*1/12+IF(Inputs!D28=1,Inputs!$B$11/12,0)+Scenarios!D8*Inputs!$B$9/12+Inputs!D27/12
A6: Rate −0.50 pt | B6: =Scenarios!B8*((Inputs!$B$5+(-0.005))/12)/(1-(1+(Inputs!$B$5+(-0.005))/12)^(-Inputs!$B$6*12))+Inputs!B26*Inputs!B24*1/12+Inputs!$B$10*1/12+IF(Inputs!B28=1,Inputs!$B$11/12,0)+Scenarios!B8*Inputs!$B$9/12+Inputs!B27/12 | C6: =Scenarios!C8*((Inputs!$B$5+(-0.005))/12)/(1-(1+(Inputs!$B$5+(-0.005))/12)^(-Inputs!$B$6*12))+Inputs!C26*Inputs!C24*1/12+Inputs!$B$10*1/12+IF(Inputs!C28=1,Inputs!$B$11/12,0)+Scenarios!C8*Inputs!$B$9/12+Inputs!C27/12 | D6: =Scenarios!D8*((Inputs!$B$5+(-0.005))/12)/(1-(1+(Inputs!$B$5+(-0.005))/12)^(-Inputs!$B$6*12))+Inputs!D26*Inputs!D24*1/12+Inputs!$B$10*1/12+IF(Inputs!D28=1,Inputs!$B$11/12,0)+Scenarios!D8*Inputs!$B$9/12+Inputs!D27/12
A7: Tax basis +10% | B7: =Scenarios!B8*((Inputs!$B$5+(0))/12)/(1-(1+(Inputs!$B$5+(0))/12)^(-Inputs!$B$6*12))+Inputs!B26*Inputs!B24*1.1/12+Inputs!$B$10*1/12+IF(Inputs!B28=1,Inputs!$B$11/12,0)+Scenarios!B8*Inputs!$B$9/12+Inputs!B27/12 | C7: =Scenarios!C8*((Inputs!$B$5+(0))/12)/(1-(1+(Inputs!$B$5+(0))/12)^(-Inputs!$B$6*12))+Inputs!C26*Inputs!C24*1.1/12+Inputs!$B$10*1/12+IF(Inputs!C28=1,Inputs!$B$11/12,0)+Scenarios!C8*Inputs!$B$9/12+Inputs!C27/12 | D7: =Scenarios!D8*((Inputs!$B$5+(0))/12)/(1-(1+(Inputs!$B$5+(0))/12)^(-Inputs!$B$6*12))+Inputs!D26*Inputs!D24*1.1/12+Inputs!$B$10*1/12+IF(Inputs!D28=1,Inputs!$B$11/12,0)+Scenarios!D8*Inputs!$B$9/12+Inputs!D27/12
A8: Tax basis −10% | B8: =Scenarios!B8*((Inputs!$B$5+(0))/12)/(1-(1+(Inputs!$B$5+(0))/12)^(-Inputs!$B$6*12))+Inputs!B26*Inputs!B24*0.9/12+Inputs!$B$10*1/12+IF(Inputs!B28=1,Inputs!$B$11/12,0)+Scenarios!B8*Inputs!$B$9/12+Inputs!B27/12 | C8: =Scenarios!C8*((Inputs!$B$5+(0))/12)/(1-(1+(Inputs!$B$5+(0))/12)^(-Inputs!$B$6*12))+Inputs!C26*Inputs!C24*0.9/12+Inputs!$B$10*1/12+IF(Inputs!C28=1,Inputs!$B$11/12,0)+Scenarios!C8*Inputs!$B$9/12+Inputs!C27/12 | D8: =Scenarios!D8*((Inputs!$B$5+(0))/12)/(1-(1+(Inputs!$B$5+(0))/12)^(-Inputs!$B$6*12))+Inputs!D26*Inputs!D24*0.9/12+Inputs!$B$10*1/12+IF(Inputs!D28=1,Inputs!$B$11/12,0)+Scenarios!D8*Inputs!$B$9/12+Inputs!D27/12
A9: Insurance +25% | B9: =Scenarios!B8*((Inputs!$B$5+(0))/12)/(1-(1+(Inputs!$B$5+(0))/12)^(-Inputs!$B$6*12))+Inputs!B26*Inputs!B24*1/12+Inputs!$B$10*1.25/12+IF(Inputs!B28=1,Inputs!$B$11/12,0)+Scenarios!B8*Inputs!$B$9/12+Inputs!B27/12 | C9: =Scenarios!C8*((Inputs!$B$5+(0))/12)/(1-(1+(Inputs!$B$5+(0))/12)^(-Inputs!$B$6*12))+Inputs!C26*Inputs!C24*1/12+Inputs!$B$10*1.25/12+IF(Inputs!C28=1,Inputs!$B$11/12,0)+Scenarios!C8*Inputs!$B$9/12+Inputs!C27/12 | D9: =Scenarios!D8*((Inputs!$B$5+(0))/12)/(1-(1+(Inputs!$B$5+(0))/12)^(-Inputs!$B$6*12))+Inputs!D26*Inputs!D24*1/12+Inputs!$B$10*1.25/12+IF(Inputs!D28=1,Inputs!$B$11/12,0)+Scenarios!D8*Inputs!$B$9/12+Inputs!D27/12
A10: Insurance +25% and rate +0.50 pt | B10: =Scenarios!B8*((Inputs!$B$5+(0.005))/12)/(1-(1+(Inputs!$B$5+(0.005))/12)^(-Inputs!$B$6*12))+Inputs!B26*Inputs!B24*1/12+Inputs!$B$10*1.25/12+IF(Inputs!B28=1,Inputs!$B$11/12,0)+Scenarios!B8*Inputs!$B$9/12+Inputs!B27/12 | C10: =Scenarios!C8*((Inputs!$B$5+(0.005))/12)/(1-(1+(Inputs!$B$5+(0.005))/12)^(-Inputs!$B$6*12))+Inputs!C26*Inputs!C24*1/12+Inputs!$B$10*1.25/12+IF(Inputs!C28=1,Inputs!$B$11/12,0)+Scenarios!C8*Inputs!$B$9/12+Inputs!C27/12 | D10: =Scenarios!D8*((Inputs!$B$5+(0.005))/12)/(1-(1+(Inputs!$B$5+(0.005))/12)^(-Inputs!$B$6*12))+Inputs!D26*Inputs!D24*1/12+Inputs!$B$10*1.25/12+IF(Inputs!D28=1,Inputs!$B$11/12,0)+Scenarios!D8*Inputs!$B$9/12+Inputs!D27/12
A12: Each case recomputes P&I, tax, insurance, MI and HOA from Inputs with the stated change; loan amount taken from Scenarios row 8 (Scenario A).

Sheet Facts
A1: SIDE-BY-SIDE FACTS (text as recorded in sources; conflicts preserved)
A3: Field | B3: 3604 Littleleaf Dr, Killeen 76549 | C3: 2201 Westcliff Rd, Killeen 76543 | D3: 2409 Patrick Henry St, Temple 76504 | E3: Source / note
A4: MLS # / status / list price | B4: 624332 / Active / $245,000 | C4: 625203 / Active / $260,000 | D4: 621224 / Active / $219,000 | E4: MLS 360 Property View, printed 10/01/2026
A5: List date / DOM | B5: 09/02/2026 / 29 | C5: 09/14/2026 / 17 (also 'Recent: 09/18/2026 New Listing') | D5: 08/19/2026 / 43 | E5: MLS
A6: Type / units / stories | B6: Multi-family duplex / 2 / one | C6: Multi-family duplex / units field blank / one | D6: Multi-family duplex / 2 / one | E6: MLS
A7: Beds/baths per unit | B7: 2 bed / 1 bath each | C7: 2 bed / 1 bath each | D7: 2 bed / 2 bath each | E7: MLS
A8: Living area (source) | B8: 1,943 sf total (Appraisal District); remarks say ~970 sf per unit | C8: 1,974 sf total (Appraisal District) | D8: 2,142 sf total (Appraisal District); agent remarks: all measurements approximate | E8: MLS
A9: Year built (source) | B9: 2003 (Appraisal District) | C9: 1999 (Appraisal District) | D9: 1981 (Appraisal District) | E9: MLS
A10: Lot | B10: 0.197 ac (Lot 9 Blk 3, Roberts Add Sec Two) | C10: 0.823 ac (Lot 4 Blk 1, Mayhorn Add) | D10: 0.182 ac (Lot 4 Blk 18, Northwest Hills 1st Ext) | E10: MLS legal description
A11: Parking | B11: Off-street, 2 per unit per table; Garage field blank; CSV Garage: None | C11: Attached garage; CSV Garage: 1 | D11: Attached carport (2); CSV Garage: None | E11: MLS + CSV export
A12: HOA | B12: None | C12: None | D12: None | E12: MLS
A13: Occupancy / leases | B13: Both vacant; Currently Leased: No | C13: Side B vacant; other side tenant month-to-month $895; tenant pays all bills; Occupant field says Vacant (conflict) | D13: One unit leased 12 months to 02/28/2027 at $995; other vacant; pro forma $995; Occupant: Tenant | E13: MLS; leases not read
A14: Documents on file | B14: Seller's Disclosure | C14: Lease Agreements | D14: Seller's Disclosure, Survey | E14: MLS
... A22: Showing | B22: Call first-go; combo lockbox back door | C22: Appointment only; side B shown, other side during option | D22: Call listing office; 24-hr notice; weekdays only | E22: MLS

Sheet Rents_Comps
A1: RENT EVIDENCE AND SUPPLIED SALES DATA (from two MLS CSV exports supplied 2026-10-01; not an appraisal)
A3: Address (Killeen unless noted) | B3: Status | C3: List $ | D3: Close $ | E3: Sq ft | F3: $/sf (close or list) | G3: Year built | H3: Config / financing | I3: Note
A4: 3802 Hitchrock Dr #1&2 | B4: Closed 04/13/2026 | C4: 289000 | D4: 289000 | E4: 2392 | F4: =IF(D4<>"",D4/E4,C4/E4) | G4: 2000 | H4: 3/2 each, 2-car gar each (per side?) / VA | I4: Roof replaced; CSV
A5: 3605 Westwood Dr | B5: Closed 04/14/2026 | C5: 290000 | D5: 285000 | E5: 2352 | F5: =IF(D5<>"",D5/E5,C5/E5) | G5: 2002 | H5: 2/2 each, 1-car / Cash | I5: Updated; new roof; CSV
A6: 2709 Alma Dr | B6: Closed 09/21/2026 | C6: 315000 | D6: 315000 | E6: 2282 | F6: =IF(D6<>"",D6/E6,C6/E6) | G6: 2002 | H6: 3/2 each, 1-car / VA | I6: Unit A leased $1,245 to 8/31/2026 then MTM; unit B updated vacant; CSV
A7: 2308 Shoemaker Dr | B7: Closed 06/15/2026 | C7: 235000 | D7: 200000 | E7: 2060 | F7: =IF(D7<>"",D7/E7,C7/E7) | G7: 1982 | H7: 3/2 + 2/1 units / Cash | I7: LP $245k orig; renovated 3/2; CSV
A8: 2105 Robert E Lee Dr (fourplex) | B8: Closed 09/24/2026 | C8: 269550 | D8: 255000 | E8: 1952 | F8: =IF(D8<>"",D8/E8,C8/E8) | G8: 1979 | H8: 4 × 1/1 / VA | I8: All units $650; owner pays water/sewer/garbage; CSV
A9: 1807 N W S Young Dr | B9: Closed 07/29/2026 | C9: 129000 | D9: 120000 | E9: 1056 | F9: =IF(D9<>"",D9/E9,C9/E9) | G9: 1964 | H9: 1/1 / Conventional | I9: Single unit of duplex? CSV
A10: 3805 Hitchrock Dr | B10: Pending | C10: 195000 | E10: 2392 | F10: =IF(D10<>"",D10/E10,C10/E10) | G10: 2000 | H10: 3/2 each | I10: As-is; 'opening offer amount'; multiple offers; CSV
A11: 2602 Alma Dr | B11: Active Under Contract | C11: 255999 | E11: 2282 | F11: =IF(D11<>"",D11/E11,C11/E11) | G11: 2002 | H11: 3/2 each, 1-car | I11: Tenant occupied; orig $285,999; CSV
A12: 2600 Edgefield St | B12: Active | C12: 280000 | E12: 2352 | F12: =IF(D12<>"",D12/E12,C12/E12) | G12: 2002 | H12: 3/2 each | I12: Portfolio seller; tenants; CSV
A13: 2606 Edgefield St | B13: Active | C13: 290000 | E13: 2352 | F13: =IF(D13<>"",D13/E13,C13/E13) | G13: 2001 | H13: 3/2 each, 1-car | I13: Vacant both; DOM 120; CSV
A14: 3501 / 3505 Dustin Ct | B14: Active | C14: 290000 | E14: 2590 | F14: =IF(D14<>"",D14/E14,C14/E14) | G14: 2003 | H14: 3/2 each | I14: Portfolio seller; CSV
A15: 2609 Vernice Loop | B15: Active | C15: 295000 | E15: 2614 | F15: =IF(D15<>"",D15/E15,C15/E15) | G15: 2006 | H15: 3/2 each | I15: Orig $309k; DOM 92; CSV
A16: 3801 Hitchrock Dr | B16: Active | C16: 330000 | E16: 2392 | F16: =IF(D16<>"",D16/E16,C16/E16) | G16: 2000 | H16: 3/2 each, 1-car | I16: DOM 729; CSV
A17: 3802 Uvalde Dr #A&B | B17: Active | C17: 260000 | E17: 2470 | F17: =IF(D17<>"",D17/E17,C17/E17) | G17: 2004 | H17: 2/2 each (per remarks) | I17: Orig $265k; lease to 7/31/2026; CSV
A18: 2209 Wright Way | B18: Active | C18: 270000 | E18: 2187 | F18: =IF(D18<>"",D18/E18,C18/E18) | G18: 1999 | H18: 3/2 each, 1-car | I18: Tenant; corner lot; CSV
A19: 2410 Westcliff Rd #A&B | B19: Active | C19: 365000 | E19: 2496 | F19: =IF(D19<>"",D19/E19,C19/E19) | G19: 2024 | H19: 3/2 each, 1-car | I19: New build; remarks conflict: 'both sides vacant' vs 'both rented at $1,200'; DOM 418; CSV
A21: Subject $/sf at list
A22: 3604 Littleleaf (2/1 each, 1,943 sf) | F22: =Inputs!B22/1943
A23: 2201 Westcliff (2/1 each, 1,974 sf) | F23: =Inputs!C22/1974
A24: 2409 Patrick Henry (2/2 each, 2,142 sf) | F24: =Inputs!D22/2142
A26: Caution: no supplied closed sale matches a 2/1-per-side duplex; no Temple comparables were supplied at all. These rows support questions, not an offer price. An offer recommendation requires an MLS comp review of similar configuration, age and condition within 6–12 months.
A28: RENT EVIDENCE (distinguish signed-lease rent, actual collections, asking rent, projected market rent)
A29: Property | B29: Signed lease / MTM rent | C29: Actual collections | D29: Asking rent | E29: Projected market rent | F29: Source
A30: 3604 Littleleaf | B30: none (vacant) | C30: none | D30: not listed | E30: unknown — no 2/1 rent evidence supplied | F30: MLS
A31: 2201 Westcliff | B31: $895 month-to-month, one side | C31: unverified | D31: not listed | E31: unknown | F31: MLS rent table; lease on file not read
A32: 2409 Patrick Henry | B32: $995, 12-month lease to 02/28/2027, one side | C32: unverified | D32: $995 pro forma for vacant side | E32: unknown | F32: MLS rent table
A33: Reference: 2709 Alma (3/2) | B33: $1,245 lease to 8/31/2026 | C33: — | D33: — | E33: — | F33: CSV remarks
A34: Reference: 2410 Westcliff (new 3/2) | B34: $1,200 each (conflicting remarks) | C34: — | D34: — | E34: — | F34: CSV remarks

Sheet Template_Blank
A1: REUSABLE SHORTLIST TEMPLATE — copy this sheet per shortlist; fill blue cells; see Inputs/Scenarios for the model
A3: Field | B3: Property 1 | C3: Property 2 | D3: Property 3 | E3: Source to cite
A4: Full address / MLS # / listing URL | B4: 3604 Littleleaf Dr, Killeen 76549 / 624332 / (MLS link) | E4: MLS sheet / CAD / FEMA / lender / insurer / buyer
A5: Asking price / status / check date | B5: $245,000 / Active / 2026-10-01 | E5: MLS sheet / CAD / FEMA / lender / insurer / buyer
A6: Home type / units / beds-baths per unit | B6: Duplex / 2 / 2-1 each | E6: MLS sheet / CAD / FEMA / lender / insurer / buyer
A7: Living area + source | B7: 1,943 sf (Appraisal District) | E7: MLS sheet / CAD / FEMA / lender / insurer / buyer
A8: Year built + source | B8: 2003 (Appraisal District) | E8: MLS sheet / CAD / FEMA / lender / insurer / buyer
A9: Lot size / legal description | B9: 0.197 ac / Roberts Add Sec Two Blk 3 Lot 9 | E9: MLS sheet / CAD / FEMA / lender / insurer / buyer
A10: Parking | B10: Off-street | E10: MLS sheet / CAD / FEMA / lender / insurer / buyer
A11: HOA (annual, what it covers) | B11: None | E11: MLS sheet / CAD / FEMA / lender / insurer / buyer
A12: Occupancy: vacant / tenant / lease end / rent (signed vs collected) | B12: Vacant / — / — / none | E12: MLS sheet / CAD / FEMA / lender / insurer / buyer
A13: Acceptable financing (per listing) | B13: Cash, Conv, FHA, VA | E13: MLS sheet / CAD / FEMA / lender / insurer / buyer
A14: Condition notes / known repairs / as-is | B14: AS-IS; light TLC; lender repairs on buyer | E14: MLS sheet / CAD / FEMA / lender / insurer / buyer
A15: Documents on file (SD, survey, leases, inspection) | B15: Seller's Disclosure | E15: MLS sheet / CAD / FEMA / lender / insurer / buyer
... A27: Missing / must verify before offer | B27: CAD value, insurance, sewer type, SD | E27: MLS sheet / CAD / FEMA / lender / insurer / buyer
A29: Column B shows an example row (Littleleaf) in the expected format; replace it. Minimum inputs before a comparison is decision-grade: buyer decision + must-haves + budget + timeline + destination; MLS sheet per property; CAD record; lender scenario; insurance quote; leases if occupied.

Sheet Source_Ledger
A1: SOURCE LEDGER — material claims, source, date, location, evidence status
A3: ID | B3: Claim | C3: Source | D3: Source date | E3: Location in source | F3: Evidence status
A4: S1 | B4: 3604 Littleleaf: Active, $245,000, 1,943 sf (Appraisal District), 2003, duplex 2/1 each, vacant, AS-IS, FHA/VA accepted, tax $4,761 @2.03 (2026), Homestead exemption, FEMA plain No | C4: MLS 360 Property View, MLS 624332 (printed by Taylor Dasch) | D4: 2026-10-01 | E4: Header; Beds/Baths table; Tax block; Agent Only Remarks | F4: MLS-reported; not independently verified
A5: S2 | B5: 2201 Westcliff: Active, $260,000, 1,974 sf (Appraisal District), 1999, 2/1 each with garage, 0.823 ac, one side MTM $895, tenant pays all bills, Cash/Conventional only, tax $5,207 @2.03 (2026), FEMA plain Partial, Res Flooded Unknown, 1 heat/1 AC/1 water heater | C5: MLS 360 Property View, MLS 625203 | D5: 2026-10-01 | E5: Header; lot block; rent table; Tax block; Amenities | F5: MLS-reported; lease on file not read
A6: S3 | B6: 2409 Patrick Henry: Active, $219,000, 2,142 sf (Appraisal District), 1981, 2/2 each, carport, one unit leased to 02/28/2027 at $995, other vacant pro forma $995, Side B HVAC 2025, Cash/Conventional only, tax amount blank @2.39 (2025), seller may consider concession, owner irrevocable trust, SD + survey on file | C6: MLS 360 Property View, MLS 621224 | D6: 2026-10-01 | E6: Header; rent table; Public Remarks; Tax block; Documents on File | F6: MLS-reported; SD/survey not read
A7: S4 | B7: Killeen duplex sales and actives (Hitchrock, Westwood, Alma, Edgefield, Dustin, Vernice, Uvalde, Littleleaf) | C7: MLS CSV export 'claude-os-data_33.csv' supplied by Taylor | D7: 2026-10-01 (export date not stamped; latest close 09/21/2026) | E7: Rows 2–14 | F7: MLS-reported; configurations differ from subject
A8: S5 | B8: Westcliff-area actives and closed small multifamily (Wright Way, 2410 Westcliff, WS Young, Robert E Lee fourplex, Shoemaker) | C8: MLS CSV export 'claude-os-data_34.csv' supplied by Taylor | D8: 2026-10-01 (export date not stamped; latest close 09/24/2026) | E8: Rows 2–7 | F8: MLS-reported; weak comparability
A9: S6 | B9: Flood zones: Littleleaf and Patrick Henry sites Zone X minimal; Westcliff within 30 m of Zone AE, AE floodway, X 0.2%; panel 48027C0115E eff. 2008-09-26 | C9: FEMA National Flood Hazard Layer REST service (hazards.fema.gov NFHL layers 28 and 3), points from U.S. Census geocoder | D9: 2026-10-01 | E9: Point/buffer queries (1–60 m) | F9: Official layer; point-level, not a flood determination or elevation certificate
A10: S7 | B10: Bell CAD appraised values, exemptions, jurisdictions | C10: esearch.bellcad.org | D10: 2026-10-01 | E10: — | F10: NOT RETRIEVED (HTTP 503 / certificate error); must be pulled by Taylor
A11: S8 | B11: 30-yr fixed rate 6.71% (week of Sept 3, 2026) | C11: Freddie Mac PMMS | D11: 2026-09-03 (latest located) | E11: Weekly release | F11: Illustrative only; not a borrower quote
A12: S9 | B12: Fannie Mae 5% down on owner-occupied 2–4 unit; 25% typical for investment 2–4 unit; FHA/VA require owner occupancy on 2–4 units; 2026 FHA 2-unit limit Bell County $693,050 (secondary sources) | C12: Industry summaries of Fannie Mae policy (Nov 2023) and FHA 2026 limits | D12: 2026-10-01 retrieval | E12: — | F12: Secondary; lender must confirm
A13: S10 | B13: Texas homestead exemption applies only to the owner-occupied portion of a duplex | C13: Texas Tax Code §11.13 as summarized in secondary sources | D13: 2026-10-01 retrieval | E13: — | F13: Secondary; Bell CAD to confirm treatment
A14: S11 | B14: Buyer decision, must-haves, budget, timeline, commute destination, lender scenario, insurance quotes, inspection reports, seller disclosures, leases | C14: Not supplied | D14: — | E14: — | F14: MISSING — fit rankings provisional

Sheet Call_Questions
A1: PRIORITIZED CALL-QUESTION SHEET (deal-stoppers first)
A3: # | B3: Property | C3: Question (plain language) | D3: Who answers | E3: Why it matters | F3: Evidence to request | G3: Decision that changes
A4: 1 | B4: 2201 Westcliff | C4: Is any part of the building (not just the lot) inside the FEMA Special Flood Hazard Area or floodway, and has it ever flooded? | D4: Listing agent → seller; surveyor/elevation certificate; insurer | E4: Lender flood insurance requirement, insurability, resale; MLS says plain Partial, Res Flooded Unknown | F4: Flood determination from lender, elevation certificate if any, seller's disclosure flood section, NFIP claims history | G4: Deal-stopper if structure is in AE/floodway with no affordable coverage
A5: 2 | B5: 2201 Westcliff + 2409 Patrick Henry | C5: Will the seller consider FHA or VA financing, or is Cash/Conventional truly the only acceptable financing? | D5: Listing agent | E5: Both listings state Cash, Conventional only; determines whether a low-down owner-occupant can buy | F5: Written confirmation; if conventional only, lender pre-approval for 5% down 2-unit | G5: Eliminates properties for an FHA/VA buyer
A6: 3 | B6: 3604 Littleleaf | C6: What repairs does 'light TLC' and 'AS-IS' cover, and will the seller allow an FHA/VA appraisal with buyer-paid repairs? | D6: Listing agent; inspector | E6: Lender-required repairs at buyer expense could add cash and delay closing | F6: Seller's disclosure (on file), inspection, photos of each unit, utility status | G6: Offer price, financing type, repair budget
A7: 4 | B7: 2409 Patrick Henry | C7: Who signs for the irrevocable trust and does title have the trust instrument/certification? | D7: Title company; listing agent | E7: Authority to convey; closing timeline | F7: Certification of trust, trustee ID | G7: Timeline; contract validity
A8: 5 | B8: All three | C8: What are the 2026 Bell CAD appraised values and which exemptions apply now; what will taxes be without the seller's exemption? | D8: Bell CAD / tax office; title (tax certificate) | E8: Littleleaf $4,761 includes a homestead; Patrick Henry amount blank; buyer treatment differs | F8: CAD record, tax certificate at title | G8: Monthly payment; affordability
A9: 6 | B9: 2201 Westcliff + 2409 Patrick Henry | C9: Lease terms for the occupied unit: rent, deposit held, lease end, late payments, who pays which utilities, any notice already given? | D9: Listing agent → seller/property manager | E9: Possession for an owner-occupant; income reliability | F9: Signed lease, rent ledger (12 months), deposit accounting, estoppel letter | G9: Move-in timing; which unit; cash flow
A10: 7 | B10: 2201 Westcliff | C10: Are heating, cooling, water heater and utility meters separate for each unit (MLS lists 1 unit each)? | D10: Listing agent; inspector; utility provider | E10: Shared systems complicate tenant billing and comfort; MLS says tenant pays all bills | F10: Meter numbers per unit, HVAC inspection | G10: Operating cost and rentability
A11: 8 | B11: 3604 Littleleaf | C11: Is the property on city sewer or an on-site septic system (MLS lists both 'City on Property' and 'On-Site Sewer')? | D11: City of Killeen utilities; seller; inspector | E11: Septic inspection, permits, replacement cost | F11: Utility account history, septic permit/inspection | G11: Inspection scope; cost
A12: 9 | B12: All three | C12: Homeowners (and flood where applicable) insurance quotes for a duplex of this age/roof | D12: Insurer | E12: Insurance is a placeholder in every scenario | F12: Bound quote per address; roof age; 4-point if required | G12: Monthly payment; lender approval
A13: 10 | B13: 2201 Westcliff | C13: Why does the sheet show In City Limits Yes and ETJ Yes, and 'Gated Community Yes'? What is the zoning and any deed restriction on the 0.823-acre lot? | D13: Listing agent; City of Killeen planning; title | E13: Jurisdiction affects permits, taxes, services; large lot may be partly unusable floodway | F13: Zoning letter, title commitment Schedule B, plat | G13: Use of lot; future value
A14: 11 | B14: All three | C14: Will the seller contribute to closing costs, and what concession terms have they accepted before? | D14: Listing agent | E14: Patrick Henry marked 'Yes'; others blank | F14: Written response; contract addendum | G14: Cash to close
A15: 12 | B15: All three | C15: Roof age, HVAC age (except Patrick Henry Side B 2025), water heater age, plumbing type, any insurance claims | D15: Seller's disclosure; inspector | E15: Near-term capital costs on 1981–2003 buildings | F15: Seller's disclosure, receipts, inspection | G15: Maintenance allowance; offer
A16: 13 | B16: Buyer | C16: Which unit will you occupy, by when, and what is your actual commute destination and schedule? | D16: Buyer | E16: Occupancy drives financing, taxes (homestead on occupied unit only) and possession timing | F16: Buyer profile | G16: Fit ranking; scenario choice
